# Watchtower 61
# Simple defensive tower with ladder and battlements
# Origin is the player's position (~ ~ ~) when running the function.

fill ~0 ~0 ~0 ~6 ~0 ~6 bricks
fill ~0 ~1 ~0 ~6 ~9 ~0 bricks
fill ~0 ~1 ~6 ~6 ~9 ~6 bricks
fill ~0 ~1 ~0 ~0 ~9 ~6 bricks
fill ~6 ~1 ~0 ~6 ~9 ~6 bricks
fill ~1 ~1 ~1 ~5 ~8 ~5 air
fill ~1 ~3 ~1 ~5 ~3 ~5 jungle_planks
fill ~1 ~6 ~1 ~5 ~6 ~5 jungle_planks
setblock ~1 ~1 ~1 ladder
setblock ~1 ~2 ~1 ladder
setblock ~1 ~3 ~1 ladder
setblock ~1 ~4 ~1 ladder
setblock ~1 ~5 ~1 ladder
setblock ~1 ~6 ~1 ladder
setblock ~1 ~7 ~1 ladder
setblock ~1 ~8 ~1 ladder
setblock ~2 ~1 ~0 air
setblock ~2 ~2 ~0 air
setblock ~3 ~3 ~0 air
setblock ~3 ~3 ~6 air
setblock ~3 ~6 ~0 air
setblock ~3 ~6 ~6 air
setblock ~0 ~10 ~0 bricks
setblock ~0 ~10 ~6 bricks
setblock ~2 ~10 ~0 bricks
setblock ~2 ~10 ~6 bricks
setblock ~4 ~10 ~0 bricks
setblock ~4 ~10 ~6 bricks
setblock ~6 ~10 ~0 bricks
setblock ~6 ~10 ~6 bricks
setblock ~0 ~10 ~0 bricks
setblock ~6 ~10 ~0 bricks
setblock ~0 ~10 ~2 bricks
setblock ~6 ~10 ~2 bricks
setblock ~0 ~10 ~4 bricks
setblock ~6 ~10 ~4 bricks
setblock ~0 ~10 ~6 bricks
setblock ~6 ~10 ~6 bricks
setblock ~3 ~11 ~3 mangrove_fence
setblock ~3 ~12 ~3 red_wool
say 🗼 Watchtower 61 complete!
