# Watchtower 74
# Simple defensive tower with ladder and battlements
# Origin is the player's position (~ ~ ~) when running the function.

fill ~0 ~0 ~0 ~5 ~0 ~5 deepslate_bricks
fill ~0 ~1 ~0 ~5 ~11 ~0 deepslate_bricks
fill ~0 ~1 ~5 ~5 ~11 ~5 deepslate_bricks
fill ~0 ~1 ~0 ~0 ~11 ~5 deepslate_bricks
fill ~5 ~1 ~0 ~5 ~11 ~5 deepslate_bricks
fill ~1 ~1 ~1 ~4 ~10 ~4 air
fill ~1 ~3 ~1 ~4 ~3 ~4 birch_planks
fill ~1 ~6 ~1 ~4 ~6 ~4 birch_planks
fill ~1 ~9 ~1 ~4 ~9 ~4 birch_planks
setblock ~1 ~1 ~1 ladder
setblock ~1 ~2 ~1 ladder
setblock ~1 ~3 ~1 ladder
setblock ~1 ~4 ~1 ladder
setblock ~1 ~5 ~1 ladder
setblock ~1 ~6 ~1 ladder
setblock ~1 ~7 ~1 ladder
setblock ~1 ~8 ~1 ladder
setblock ~1 ~9 ~1 ladder
setblock ~1 ~10 ~1 ladder
setblock ~2 ~1 ~0 air
setblock ~2 ~2 ~0 air
setblock ~2 ~3 ~0 air
setblock ~2 ~3 ~5 air
setblock ~2 ~6 ~0 air
setblock ~2 ~6 ~5 air
setblock ~2 ~9 ~0 air
setblock ~2 ~9 ~5 air
setblock ~0 ~12 ~0 deepslate_bricks
setblock ~0 ~12 ~5 deepslate_bricks
setblock ~2 ~12 ~0 deepslate_bricks
setblock ~2 ~12 ~5 deepslate_bricks
setblock ~4 ~12 ~0 deepslate_bricks
setblock ~4 ~12 ~5 deepslate_bricks
setblock ~0 ~12 ~0 deepslate_bricks
setblock ~5 ~12 ~0 deepslate_bricks
setblock ~0 ~12 ~2 deepslate_bricks
setblock ~5 ~12 ~2 deepslate_bricks
setblock ~0 ~12 ~4 deepslate_bricks
setblock ~5 ~12 ~4 deepslate_bricks
setblock ~2 ~13 ~2 dark_oak_fence
setblock ~2 ~14 ~2 red_wool
say 🗼 Watchtower 74 complete!
