# Watchtower 269
# Simple defensive tower with ladder and battlements
# Origin is the player's position (~ ~ ~) when running the function.

fill ~0 ~0 ~0 ~5 ~0 ~5 sandstone
fill ~0 ~1 ~0 ~5 ~10 ~0 sandstone
fill ~0 ~1 ~5 ~5 ~10 ~5 sandstone
fill ~0 ~1 ~0 ~0 ~10 ~5 sandstone
fill ~5 ~1 ~0 ~5 ~10 ~5 sandstone
fill ~1 ~1 ~1 ~4 ~9 ~4 air
fill ~1 ~3 ~1 ~4 ~3 ~4 smooth_sandstone
fill ~1 ~6 ~1 ~4 ~6 ~4 smooth_sandstone
fill ~1 ~9 ~1 ~4 ~9 ~4 smooth_sandstone
setblock ~1 ~1 ~1 ladder
setblock ~1 ~2 ~1 ladder
setblock ~1 ~3 ~1 ladder
setblock ~1 ~4 ~1 ladder
setblock ~1 ~5 ~1 ladder
setblock ~1 ~6 ~1 ladder
setblock ~1 ~7 ~1 ladder
setblock ~1 ~8 ~1 ladder
setblock ~1 ~9 ~1 ladder
setblock ~2 ~1 ~0 air
setblock ~2 ~2 ~0 air
setblock ~2 ~3 ~0 air
setblock ~2 ~3 ~5 air
setblock ~2 ~6 ~0 air
setblock ~2 ~6 ~5 air
setblock ~2 ~9 ~0 air
setblock ~2 ~9 ~5 air
setblock ~0 ~11 ~0 sandstone
setblock ~0 ~11 ~5 sandstone
setblock ~2 ~11 ~0 sandstone
setblock ~2 ~11 ~5 sandstone
setblock ~4 ~11 ~0 sandstone
setblock ~4 ~11 ~5 sandstone
setblock ~0 ~11 ~0 sandstone
setblock ~5 ~11 ~0 sandstone
setblock ~0 ~11 ~2 sandstone
setblock ~5 ~11 ~2 sandstone
setblock ~0 ~11 ~4 sandstone
setblock ~5 ~11 ~4 sandstone
setblock ~2 ~12 ~2 acacia_fence
setblock ~2 ~13 ~2 red_wool
say 🗼 Watchtower 269 complete!
