# Watchtower 272
# Simple defensive tower with ladder and battlements
# Origin is the player's position (~ ~ ~) when running the function.

fill ~0 ~0 ~0 ~4 ~0 ~4 prismarine_bricks
fill ~0 ~1 ~0 ~4 ~11 ~0 prismarine_bricks
fill ~0 ~1 ~4 ~4 ~11 ~4 prismarine_bricks
fill ~0 ~1 ~0 ~0 ~11 ~4 prismarine_bricks
fill ~4 ~1 ~0 ~4 ~11 ~4 prismarine_bricks
fill ~1 ~1 ~1 ~3 ~10 ~3 air
fill ~1 ~3 ~1 ~3 ~3 ~3 stripped_warped_stem
fill ~1 ~6 ~1 ~3 ~6 ~3 stripped_warped_stem
fill ~1 ~9 ~1 ~3 ~9 ~3 stripped_warped_stem
setblock ~1 ~1 ~1 ladder
setblock ~1 ~2 ~1 ladder
setblock ~1 ~3 ~1 ladder
setblock ~1 ~4 ~1 ladder
setblock ~1 ~5 ~1 ladder
setblock ~1 ~6 ~1 ladder
setblock ~1 ~7 ~1 ladder
setblock ~1 ~8 ~1 ladder
setblock ~1 ~9 ~1 ladder
setblock ~1 ~10 ~1 ladder
setblock ~2 ~1 ~0 air
setblock ~2 ~2 ~0 air
setblock ~2 ~3 ~0 air
setblock ~2 ~3 ~4 air
setblock ~2 ~6 ~0 air
setblock ~2 ~6 ~4 air
setblock ~2 ~9 ~0 air
setblock ~2 ~9 ~4 air
setblock ~0 ~12 ~0 prismarine_bricks
setblock ~0 ~12 ~4 prismarine_bricks
setblock ~2 ~12 ~0 prismarine_bricks
setblock ~2 ~12 ~4 prismarine_bricks
setblock ~4 ~12 ~0 prismarine_bricks
setblock ~4 ~12 ~4 prismarine_bricks
setblock ~0 ~12 ~0 prismarine_bricks
setblock ~4 ~12 ~0 prismarine_bricks
setblock ~0 ~12 ~2 prismarine_bricks
setblock ~4 ~12 ~2 prismarine_bricks
setblock ~0 ~12 ~4 prismarine_bricks
setblock ~4 ~12 ~4 prismarine_bricks
setblock ~2 ~13 ~2 warped_fence
setblock ~2 ~14 ~2 red_wool
say 🗼 Watchtower 272 complete!
