# Watchtower 297
# Simple defensive tower with ladder and battlements
# Origin is the player's position (~ ~ ~) when running the function.

fill ~0 ~0 ~0 ~6 ~0 ~6 sandstone
fill ~0 ~1 ~0 ~6 ~11 ~0 sandstone
fill ~0 ~1 ~6 ~6 ~11 ~6 sandstone
fill ~0 ~1 ~0 ~0 ~11 ~6 sandstone
fill ~6 ~1 ~0 ~6 ~11 ~6 sandstone
fill ~1 ~1 ~1 ~5 ~10 ~5 air
fill ~1 ~3 ~1 ~5 ~3 ~5 smooth_sandstone
fill ~1 ~6 ~1 ~5 ~6 ~5 smooth_sandstone
fill ~1 ~9 ~1 ~5 ~9 ~5 smooth_sandstone
setblock ~1 ~1 ~1 ladder
setblock ~1 ~2 ~1 ladder
setblock ~1 ~3 ~1 ladder
setblock ~1 ~4 ~1 ladder
setblock ~1 ~5 ~1 ladder
setblock ~1 ~6 ~1 ladder
setblock ~1 ~7 ~1 ladder
setblock ~1 ~8 ~1 ladder
setblock ~1 ~9 ~1 ladder
setblock ~1 ~10 ~1 ladder
setblock ~2 ~1 ~0 air
setblock ~2 ~2 ~0 air
setblock ~3 ~3 ~0 air
setblock ~3 ~3 ~6 air
setblock ~3 ~6 ~0 air
setblock ~3 ~6 ~6 air
setblock ~3 ~9 ~0 air
setblock ~3 ~9 ~6 air
setblock ~0 ~12 ~0 sandstone
setblock ~0 ~12 ~6 sandstone
setblock ~2 ~12 ~0 sandstone
setblock ~2 ~12 ~6 sandstone
setblock ~4 ~12 ~0 sandstone
setblock ~4 ~12 ~6 sandstone
setblock ~6 ~12 ~0 sandstone
setblock ~6 ~12 ~6 sandstone
setblock ~0 ~12 ~0 sandstone
setblock ~6 ~12 ~0 sandstone
setblock ~0 ~12 ~2 sandstone
setblock ~6 ~12 ~2 sandstone
setblock ~0 ~12 ~4 sandstone
setblock ~6 ~12 ~4 sandstone
setblock ~0 ~12 ~6 sandstone
setblock ~6 ~12 ~6 sandstone
setblock ~3 ~13 ~3 acacia_fence
setblock ~3 ~14 ~3 red_wool
say 🗼 Watchtower 297 complete!
