# Watchtower 299
# Simple defensive tower with ladder and battlements
# Origin is the player's position (~ ~ ~) when running the function.

fill ~0 ~0 ~0 ~6 ~0 ~6 stone_bricks
fill ~0 ~1 ~0 ~6 ~10 ~0 stone_bricks
fill ~0 ~1 ~6 ~6 ~10 ~6 stone_bricks
fill ~0 ~1 ~0 ~0 ~10 ~6 stone_bricks
fill ~6 ~1 ~0 ~6 ~10 ~6 stone_bricks
fill ~1 ~1 ~1 ~5 ~9 ~5 air
fill ~1 ~3 ~1 ~5 ~3 ~5 oak_planks
fill ~1 ~6 ~1 ~5 ~6 ~5 oak_planks
fill ~1 ~9 ~1 ~5 ~9 ~5 oak_planks
setblock ~1 ~1 ~1 ladder
setblock ~1 ~2 ~1 ladder
setblock ~1 ~3 ~1 ladder
setblock ~1 ~4 ~1 ladder
setblock ~1 ~5 ~1 ladder
setblock ~1 ~6 ~1 ladder
setblock ~1 ~7 ~1 ladder
setblock ~1 ~8 ~1 ladder
setblock ~1 ~9 ~1 ladder
setblock ~2 ~1 ~0 air
setblock ~2 ~2 ~0 air
setblock ~3 ~3 ~0 air
setblock ~3 ~3 ~6 air
setblock ~3 ~6 ~0 air
setblock ~3 ~6 ~6 air
setblock ~3 ~9 ~0 air
setblock ~3 ~9 ~6 air
setblock ~0 ~11 ~0 stone_bricks
setblock ~0 ~11 ~6 stone_bricks
setblock ~2 ~11 ~0 stone_bricks
setblock ~2 ~11 ~6 stone_bricks
setblock ~4 ~11 ~0 stone_bricks
setblock ~4 ~11 ~6 stone_bricks
setblock ~6 ~11 ~0 stone_bricks
setblock ~6 ~11 ~6 stone_bricks
setblock ~0 ~11 ~0 stone_bricks
setblock ~6 ~11 ~0 stone_bricks
setblock ~0 ~11 ~2 stone_bricks
setblock ~6 ~11 ~2 stone_bricks
setblock ~0 ~11 ~4 stone_bricks
setblock ~6 ~11 ~4 stone_bricks
setblock ~0 ~11 ~6 stone_bricks
setblock ~6 ~11 ~6 stone_bricks
setblock ~3 ~12 ~3 oak_fence
setblock ~3 ~13 ~3 red_wool
say 🗼 Watchtower 299 complete!
