# Watchtower 443
# Simple defensive tower with ladder and battlements
# Origin is the player's position (~ ~ ~) when running the function.

fill ~0 ~0 ~0 ~5 ~0 ~5 deepslate_bricks
fill ~0 ~1 ~0 ~5 ~8 ~0 deepslate_bricks
fill ~0 ~1 ~5 ~5 ~8 ~5 deepslate_bricks
fill ~0 ~1 ~0 ~0 ~8 ~5 deepslate_bricks
fill ~5 ~1 ~0 ~5 ~8 ~5 deepslate_bricks
fill ~1 ~1 ~1 ~4 ~7 ~4 air
fill ~1 ~3 ~1 ~4 ~3 ~4 birch_planks
fill ~1 ~6 ~1 ~4 ~6 ~4 birch_planks
setblock ~1 ~1 ~1 ladder
setblock ~1 ~2 ~1 ladder
setblock ~1 ~3 ~1 ladder
setblock ~1 ~4 ~1 ladder
setblock ~1 ~5 ~1 ladder
setblock ~1 ~6 ~1 ladder
setblock ~1 ~7 ~1 ladder
setblock ~2 ~1 ~0 air
setblock ~2 ~2 ~0 air
setblock ~2 ~3 ~0 air
setblock ~2 ~3 ~5 air
setblock ~2 ~6 ~0 air
setblock ~2 ~6 ~5 air
setblock ~0 ~9 ~0 deepslate_bricks
setblock ~0 ~9 ~5 deepslate_bricks
setblock ~2 ~9 ~0 deepslate_bricks
setblock ~2 ~9 ~5 deepslate_bricks
setblock ~4 ~9 ~0 deepslate_bricks
setblock ~4 ~9 ~5 deepslate_bricks
setblock ~0 ~9 ~0 deepslate_bricks
setblock ~5 ~9 ~0 deepslate_bricks
setblock ~0 ~9 ~2 deepslate_bricks
setblock ~5 ~9 ~2 deepslate_bricks
setblock ~0 ~9 ~4 deepslate_bricks
setblock ~5 ~9 ~4 deepslate_bricks
setblock ~2 ~10 ~2 dark_oak_fence
setblock ~2 ~11 ~2 red_wool
say 🗼 Watchtower 443 complete!
