# Watchtower 474
# Simple defensive tower with ladder and battlements
# Origin is the player's position (~ ~ ~) when running the function.

fill ~0 ~0 ~0 ~6 ~0 ~6 prismarine_bricks
fill ~0 ~1 ~0 ~6 ~8 ~0 prismarine_bricks
fill ~0 ~1 ~6 ~6 ~8 ~6 prismarine_bricks
fill ~0 ~1 ~0 ~0 ~8 ~6 prismarine_bricks
fill ~6 ~1 ~0 ~6 ~8 ~6 prismarine_bricks
fill ~1 ~1 ~1 ~5 ~7 ~5 air
fill ~1 ~3 ~1 ~5 ~3 ~5 stripped_warped_stem
fill ~1 ~6 ~1 ~5 ~6 ~5 stripped_warped_stem
setblock ~1 ~1 ~1 ladder
setblock ~1 ~2 ~1 ladder
setblock ~1 ~3 ~1 ladder
setblock ~1 ~4 ~1 ladder
setblock ~1 ~5 ~1 ladder
setblock ~1 ~6 ~1 ladder
setblock ~1 ~7 ~1 ladder
setblock ~2 ~1 ~0 air
setblock ~2 ~2 ~0 air
setblock ~3 ~3 ~0 air
setblock ~3 ~3 ~6 air
setblock ~3 ~6 ~0 air
setblock ~3 ~6 ~6 air
setblock ~0 ~9 ~0 prismarine_bricks
setblock ~0 ~9 ~6 prismarine_bricks
setblock ~2 ~9 ~0 prismarine_bricks
setblock ~2 ~9 ~6 prismarine_bricks
setblock ~4 ~9 ~0 prismarine_bricks
setblock ~4 ~9 ~6 prismarine_bricks
setblock ~6 ~9 ~0 prismarine_bricks
setblock ~6 ~9 ~6 prismarine_bricks
setblock ~0 ~9 ~0 prismarine_bricks
setblock ~6 ~9 ~0 prismarine_bricks
setblock ~0 ~9 ~2 prismarine_bricks
setblock ~6 ~9 ~2 prismarine_bricks
setblock ~0 ~9 ~4 prismarine_bricks
setblock ~6 ~9 ~4 prismarine_bricks
setblock ~0 ~9 ~6 prismarine_bricks
setblock ~6 ~9 ~6 prismarine_bricks
setblock ~3 ~10 ~3 warped_fence
setblock ~3 ~11 ~3 red_wool
say 🗼 Watchtower 474 complete!
