# Watchtower 475
# Simple defensive tower with ladder and battlements
# Origin is the player's position (~ ~ ~) when running the function.

fill ~0 ~0 ~0 ~4 ~0 ~4 stone_bricks
fill ~0 ~1 ~0 ~4 ~8 ~0 stone_bricks
fill ~0 ~1 ~4 ~4 ~8 ~4 stone_bricks
fill ~0 ~1 ~0 ~0 ~8 ~4 stone_bricks
fill ~4 ~1 ~0 ~4 ~8 ~4 stone_bricks
fill ~1 ~1 ~1 ~3 ~7 ~3 air
fill ~1 ~3 ~1 ~3 ~3 ~3 oak_planks
fill ~1 ~6 ~1 ~3 ~6 ~3 oak_planks
setblock ~1 ~1 ~1 ladder
setblock ~1 ~2 ~1 ladder
setblock ~1 ~3 ~1 ladder
setblock ~1 ~4 ~1 ladder
setblock ~1 ~5 ~1 ladder
setblock ~1 ~6 ~1 ladder
setblock ~1 ~7 ~1 ladder
setblock ~2 ~1 ~0 air
setblock ~2 ~2 ~0 air
setblock ~2 ~3 ~0 air
setblock ~2 ~3 ~4 air
setblock ~2 ~6 ~0 air
setblock ~2 ~6 ~4 air
setblock ~0 ~9 ~0 stone_bricks
setblock ~0 ~9 ~4 stone_bricks
setblock ~2 ~9 ~0 stone_bricks
setblock ~2 ~9 ~4 stone_bricks
setblock ~4 ~9 ~0 stone_bricks
setblock ~4 ~9 ~4 stone_bricks
setblock ~0 ~9 ~0 stone_bricks
setblock ~4 ~9 ~0 stone_bricks
setblock ~0 ~9 ~2 stone_bricks
setblock ~4 ~9 ~2 stone_bricks
setblock ~0 ~9 ~4 stone_bricks
setblock ~4 ~9 ~4 stone_bricks
setblock ~2 ~10 ~2 oak_fence
setblock ~2 ~11 ~2 red_wool
say 🗼 Watchtower 475 complete!
